<?xml version="1.0" encoding="utf-8"?>
<!-- This URDF was automatically created by SolidWorks to URDF Exporter! Originally created by Stephen Brawner (brawner@gmail.com) 
     Commit Version: 1.6.0-4-g7f85cfe  Build Version: 1.6.7995.38578
     For more information, please see http://wiki.ros.org/sw_urdf_exporter -->
<robot
  name="mpccube">
  <link
    name="base_link">
    <inertial>
      <origin
        xyz="0 0 0"
        rpy="0 0 0" />
      <mass
        value="1.75" />
      <inertia
        ixx="0.0094"
        ixy="0"
        ixz="0"
        iyy="0.0073"
        iyz="0"
        izz="0.108" />
    </inertial>
    <visual>
      <origin
        xyz="0 0 0"
        rpy="0 0 0" />
      <geometry>
        <mesh
          filename="package://mpccube/meshes/base_link.STL" />
      </geometry>
      <material
        name="">
        <color
          rgba="0.792156862745098 0.819607843137255 0.933333333333333 1" />
      </material>
    </visual>
    <collision>
      <origin
        xyz="0 0 0"
        rpy="0 0 0" />
      <geometry>
        <box size = "0.4 0.25 0.125" />
      </geometry>
    </collision>
  </link>
  <link
    name="propbackright">
    <inertial>
      <origin
        xyz="0 0 0"
        rpy="0 0 0" />
      <mass
        value="0.08" />
      <inertia
        ixx="0.00004"
        ixy="0"
        ixz="0"
        iyy="0.00004"
        iyz="0"
        izz="0.000025" />
    </inertial>
    <visual>
      <origin
        xyz="0 0 0"
        rpy="0 0 0" />
      <geometry>
        <mesh
          filename="package://mpccube/meshes/propbackright.STL" scale="0.8 0.8 0.8"/>
      </geometry>
      <material
        name="">
        <color
          rgba="0.294117647058824 0.294117647058824 0.294117647058824 1" />
      </material>
    </visual>
    <collision>
      <origin
        xyz="0 0 0"
        rpy="0 0 0" />
      <geometry>
        <mesh
          filename="package://mpccube/meshes/propbackright.STL" scale="0.8 0.8 0.8"/>
      </geometry>
    </collision>
  </link>
  <joint
    name="pbr"
    type="continuous">
    <origin
      xyz="-0.1845 -0.219 0"
      rpy="0 0 0" />
    <parent
      link="base_link" />
    <child
      link="propbackright" />
    <axis
      xyz="0 0 -1" />
  </joint>
  <link
    name="propbackleft">
    <inertial>
      <origin
        xyz="0 0 0"
        rpy="0 0 0" />
      <mass
        value="0.08" />
      <inertia
        ixx="0.00004"
        ixy="0"
        ixz="0"
        iyy="0.00004"
        iyz="0"
        izz="0.000025" />
    </inertial>
    <visual>
      <origin
        xyz="0 0 0"
        rpy="0 0 0" />
      <geometry>
        <mesh
          filename="package://mpccube/meshes/propbackleft.STL" scale="0.8 0.8 0.8"/>
      </geometry>
      <material
        name="">
        <color
          rgba="0.294117647058824 0.294117647058824 0.294117647058824 1" />
      </material>
    </visual>
    <collision>
      <origin
        xyz="0 0 0"
        rpy="0 0 0" />
      <geometry>
        <mesh
          filename="package://mpccube/meshes/propbackleft.STL" scale="0.8 0.8 0.8"/>
      </geometry>
    </collision>
  </link>
  <joint
    name="pbl"
    type="continuous">
    <origin
      xyz="-0.1845 0.219 0"
      rpy="0 0 0" />
    <parent
      link="base_link" />
    <child
      link="propbackleft" />
    <axis
      xyz="0 0 -1" />
  </joint>
  <link
    name="propfrontright">
    <inertial>
      <origin
        xyz="0 0 0"
        rpy="0 0 0" />
      <mass
        value="0.08" />
      <inertia
        ixx="0.00004"
        ixy="0"
        ixz="0"
        iyy="0.00004"
        iyz="0"
        izz="0.000025" />
    </inertial>
    <visual>
      <origin
        xyz="0 0 0"
        rpy="0 0 0" />
      <geometry>
        <mesh
          filename="package://mpccube/meshes/propfrontright.STL" scale="0.8 0.8 0.8"/>
      </geometry>
      <material
        name="">
        <color
          rgba="0.294117647058824 0.294117647058824 0.294117647058824 1" />
      </material>
    </visual>
    <collision>
      <origin
        xyz="0 0 0"
        rpy="0 0 0" />
      <geometry>
        <mesh
          filename="package://mpccube/meshes/propfrontright.STL" scale="0.8 0.8 0.8"/>
      </geometry>
    </collision>
  </link>
  <joint
    name="pfr"
    type="continuous">
    <origin
      xyz="0.1845 -0.219 0"
      rpy="0 0 0" />
    <parent
      link="base_link" />
    <child
      link="propfrontright" />
    <axis
      xyz="0 0 -1" />
  </joint>
  <link
    name="propfrontleft">
    <inertial>
      <origin
        xyz="0 0 0"
        rpy="0 0 0" />
      <mass
        value="0.08" />
      <inertia
        ixx="0.00004"
        ixy="0"
        ixz="0"
        iyy="0.00004"
        iyz="0"
        izz="0.000025" />
    </inertial>
    <visual>
      <origin
        xyz="0 0 0"
        rpy="0 0 0" />
      <geometry>
        <mesh
          filename="package://mpccube/meshes/propfrontleft.STL" scale="0.8 0.8 0.8"/>
      </geometry>
      <material
        name="">
        <color
          rgba="0.294117647058824 0.294117647058824 0.294117647058824 1" />
      </material>
    </visual>
    <collision>
      <origin
        xyz="0 0 0"
        rpy="0 0 0" />
      <geometry>
        <mesh
          filename="package://mpccube/meshes/propfrontleft.STL" scale="0.8 0.8 0.8"/>
      </geometry>
    </collision>
  </link>
  <joint
    name="pfl"
    type="continuous">
    <origin
      xyz="0.1845 0.219 0"
      rpy="0 0 0" />
    <parent
      link="base_link" />
    <child
      link="propfrontleft" />
    <axis
      xyz="0 0 -1" />
  </joint>
  <link
    name="propbackrighttop">
    <inertial>
      <origin
        xyz="0 0 0"
        rpy="0 0 0" />
      <mass
        value="0.08" />
      <inertia
        ixx="0.00004"
        ixy="0"
        ixz="0"
        iyy="0.00004"
        iyz="0"
        izz="0.000025" />
    </inertial>
    <visual>
      <origin
        xyz="0 0 0"
        rpy="0 0 0" />
      <geometry>
        <mesh
          filename="package://mpccube/meshes/propbackrighttop.STL" scale="0.8 0.8 0.8"/>
      </geometry>
      <material
        name="">
        <color
          rgba="0.294117647058824 0.294117647058824 0.294117647058824 1" />
      </material>
    </visual>
    <collision>
      <origin
        xyz="0 0 0"
        rpy="0 0 0" />
      <geometry>
        <mesh
          filename="package://mpccube/meshes/propbackrighttop.STL" scale="0.8 0.8 0.8"/>
      </geometry>
    </collision>
  </link>
  <joint
    name="pbrt"
    type="continuous">
    <origin
      xyz="-0.1845 -0.219 0.18822"
      rpy="0 0 0" />
    <parent
      link="base_link" />
    <child
      link="propbackrighttop" />
    <axis
      xyz="0 0 -1" />
  </joint>
  <link
    name="propbacklefttop">
    <inertial>
      <origin
        xyz="0 0 0"
        rpy="0 0 0" />
      <mass
        value="0.08" />
      <inertia
        ixx="0.00004"
        ixy="0"
        ixz="0"
        iyy="0.00004"
        iyz="0"
        izz="0.000025" />
    </inertial>
    <visual>
      <origin
        xyz="0 0 0"
        rpy="0 0 0" />
      <geometry>
        <mesh
          filename="package://mpccube/meshes/propbacklefttop.STL" scale="0.8 0.8 0.8"/>
      </geometry>
      <material
        name="">
        <color
          rgba="0.294117647058824 0.294117647058824 0.294117647058824 1" />
      </material>
    </visual>
    <collision>
      <origin
        xyz="0 0 0"
        rpy="0 0 0" />
      <geometry>
        <mesh
          filename="package://mpccube/meshes/propbacklefttop.STL" scale="0.8 0.8 0.8"/>
      </geometry>
    </collision>
  </link>
  <joint
    name="pblt"
    type="continuous">
    <origin
      xyz="-0.1845 0.219 0.18822"
      rpy="0 0 0" />
    <parent
      link="base_link" />
    <child
      link="propbacklefttop" />
    <axis
      xyz="0 0 -1" />
  </joint>
  <link
    name="propfrontrighttop">
    <inertial>
      <origin
        xyz="0 0 0"
        rpy="0 0 0" />
      <mass
        value="0.08" />
      <inertia
        ixx="0.00004"
        ixy="0"
        ixz="0"
        iyy="0.00004"
        iyz="0"
        izz="0.000025" />
    </inertial>
    <visual>
      <origin
        xyz="0 0 0"
        rpy="0 0 0" />
      <geometry>
        <mesh
          filename="package://mpccube/meshes/propfrontrighttop.STL" scale="0.8 0.8 0.8"/>
      </geometry>
      <material
        name="">
        <color
          rgba="0.294117647058824 0.294117647058824 0.294117647058824 1" />
      </material>
    </visual>
    <collision>
      <origin
        xyz="0 0 0"
        rpy="0 0 0" />
      <geometry>
        <mesh
          filename="package://mpccube/meshes/propfrontrighttop.STL" scale="0.8 0.8 0.8"/>
      </geometry>
    </collision>
  </link>
  <joint
    name="pfrt"
    type="continuous">
    <origin
      xyz="0.1845 -0.219 0.18822"
      rpy="0 0 0" />
    <parent
      link="base_link" />
    <child
      link="propfrontrighttop" />
    <axis
      xyz="0 0 -1" />
  </joint>
  <link
    name="propfrontlefttop">
    <inertial>
      <origin
        xyz="0 0 0"
        rpy="0 0 0" />
      <mass
        value="0.08" />
      <inertia
        ixx="0.00004"
        ixy="0"
        ixz="0"
        iyy="0.00004"
        iyz="0"
        izz="0.000025" />
    </inertial>
    <visual>
      <origin
        xyz="0 0 0"
        rpy="0 0 0" />
      <geometry>
        <mesh
          filename="package://mpccube/meshes/propfrontlefttop.STL" scale="0.8 0.8 0.8"/>
      </geometry>
      <material
        name="">
        <color
          rgba="0.294117647058824 0.294117647058824 0.294117647058824 1" />
      </material>
    </visual>
    <collision>
      <origin
        xyz="0 0 0"
        rpy="0 0 0" />
      <geometry>
        <mesh
          filename="package://mpccube/meshes/propfrontlefttop.STL" scale="0.8 0.8 0.8"/>
      </geometry>
    </collision>
  </link>
  <joint
    name="pflt"
    type="continuous">
    <origin
      xyz="0.1845 0.219 0.18822"
      rpy="0 0 0" />
    <parent
      link="base_link" />
    <child
      link="propfrontlefttop" />
    <axis
      xyz="0 0 -1" />
  </joint>
  <link
    name="propmidright">
    <inertial>
      <origin
        xyz="0 0 0"
        rpy="0 0 0" />
      <mass
        value="0.00027" />
      <inertia
        ixx="0.00004"
        ixy="0"
        ixz="0"
        iyy="0.00004"
        iyz="0"
        izz="0.000025" />
    </inertial>
    <visual>
      <origin
        xyz="0 0 0"
        rpy="0 0 0" />
      <geometry>
        <mesh
          filename="package://mpccube/meshes/propmidright.STL" scale="0.8 0.8 0.8"/>
      </geometry>
      <material
        name="">
        <color
          rgba="0.792156862745098 0.819607843137255 0.933333333333333 1" />
      </material>
    </visual>
    <collision>
      <origin
        xyz="0 0 0"
        rpy="0 0 0" />
      <geometry>
        <mesh
          filename="package://mpccube/meshes/propmidright.STL" scale="0.8 0.8 0.8"/>
      </geometry>
    </collision>
  </link>
  <joint
    name="pmr"
    type="continuous">
    <origin
      xyz="-0.1845 -0.06 0.095"
      rpy="1.571 0 0" />
    <parent
      link="base_link" />
    <child
      link="propmidright" />
    <axis
      xyz="0 0 -1" />
  </joint>
  <link
    name="propmidleft">
    <inertial>
      <origin
        xyz="0 0 0"
        rpy="0 0 0" />
      <mass
        value="0.00027" /> <!-- The  -->
      <inertia
        ixx="0.00004"
        ixy="0"
        ixz="0"
        iyy="0.00004"
        iyz="0"
        izz="0.000025" />
    </inertial>
    <visual>
      <origin
        xyz="0 0 0"
        rpy="0 0 0" />
      <geometry>
        <mesh
          filename="package://mpccube/meshes/propmidleft.STL" scale="0.8 0.8 0.8"/>
      </geometry>
      <material
        name="">
        <color
          rgba="0.792156862745098 0.819607843137255 0.933333333333333 1" />
      </material>
    </visual>
    <collision>
      <origin
        xyz="0 0 0"
        rpy="0 0 0" />
      <geometry>
        <mesh
          filename="package://mpccube/meshes/propmidleft.STL" scale="0.8 0.8 0.8"/>
      </geometry>
    </collision>
  </link>
  <joint
    name="pml"
    type="continuous">
    <origin
      xyz="0.1845 -0.06 0.095"
      rpy="1.571 0 0" />
    <parent
      link="base_link" />
    <child
      link="propmidleft" />
    <axis
      xyz="0 0 -1" />
  </joint>
  <link
    name="wheelbackright">
    <inertial>
      <origin
        xyz="0 0 0"
        rpy="0 0 0" />
      <mass
        value="0.05" />
      <inertia
        ixx="7.16E-06"
        ixy="0"
        ixz="0"
        iyy="3.6E-06"
        iyz="0"
        izz="3.6E-06" />
    </inertial>
    <visual>
      <origin
        xyz="0 0 0"
        rpy="0 0 0" />
      <geometry>
        <mesh
          filename="package://mpccube/meshes/wheelbackright.STL" />
      </geometry>
      <material
        name="">
        <color
          rgba="0.792156862745098 0.819607843137255 0.933333333333333 1" />
      </material>
    </visual>
    <collision>
      <origin
        xyz="0 0 0"
        rpy="0 0 0" />
      <geometry>
        <mesh
          filename="package://mpccube/meshes/wheelbackright.STL" />
      </geometry>
    </collision>
  </link>
  <joint
    name="wbr"
    type="continuous">
    <origin
      xyz="0.189 -0.31 -0.142"
      rpy="0 0 0" />
    <parent
      link="base_link" />
    <child
      link="wheelbackright" />
    <axis
      xyz="1 0 0" />
  </joint>
  <link
    name="wheelbackleft">
    <inertial>
      <origin
        xyz="0 0 0"
        rpy="0 0 0" />
      <mass
        value="0.05" />
      <inertia
        ixx="7.16E-06"
        ixy="0"
        ixz="0"
        iyy="3.6E-06"
        iyz="0"
        izz="3.6E-06" />
    </inertial>
    <visual>
      <origin
        xyz="0 0 0"
        rpy="0 0 0" />
      <geometry>
        <mesh
          filename="package://mpccube/meshes/wheelbackleft.STL" />
      </geometry>
      <material
        name="">
        <color
          rgba="0.792156862745098 0.819607843137255 0.933333333333333 1" />
      </material>
    </visual>
    <collision>
      <origin
        xyz="0 0 0"
        rpy="0 0 0" />
      <geometry>
        <mesh
          filename="package://mpccube/meshes/wheelbackleft.STL" />
      </geometry>
    </collision>
  </link>
  <joint
    name="wbl"
    type="continuous">
    <origin
      xyz="-0.189 -0.31 -0.142"
      rpy="0 0 0" />
    <parent
      link="base_link" />
    <child
      link="wheelbackleft" />
    <axis
      xyz="1 0 0" />
  </joint>
  <link
    name="wheelfrontright">
    <inertial>
      <origin
        xyz="0 0 0"
        rpy="0 0 0" />
      <mass
        value="0.05" />
      <inertia
        ixx="7.16E-06"
        ixy="0"
        ixz="0"
        iyy="3.6E-06"
        iyz="0"
        izz="3.6E-06" />
    </inertial>
    <visual>
      <origin
        xyz="0 0 0"
        rpy="0 0 0" />
      <geometry>
        <mesh
          filename="package://mpccube/meshes/wheelfrontright.STL" />
      </geometry>
      <material
        name="">
        <color
          rgba="0.792156862745098 0.819607843137255 0.933333333333333 1" />
      </material>
    </visual>
    <collision>
      <origin
        xyz="0 0 0"
        rpy="0 0 0" />
      <geometry>
        <mesh
          filename="package://mpccube/meshes/wheelfrontright.STL" />
      </geometry>
    </collision>
  </link>
  <joint
    name="wfr"
    type="continuous">
    <origin
      xyz="0.189 0.31 -0.142"
      rpy="0 0 0" />
    <parent
      link="base_link" />
    <child
      link="wheelfrontright" />
    <axis
      xyz="-1 0 0" />
  </joint>
  <link
    name="wheelfrontleft">
    <inertial>
      <origin
        xyz="0 0 0"
        rpy="0 0 0" />
      <mass
        value="0.05" />
      <inertia
        ixx="7.16E-06"
        ixy="0"
        ixz="0"
        iyy="3.6E-06"
        iyz="0"
        izz="3.6E-06" />
    </inertial>
    <visual>
      <origin
        xyz="0 0 0"
        rpy="0 0 0" />
      <geometry>
        <mesh
          filename="package://mpccube/meshes/wheelfrontleft.STL" />
      </geometry>
      <material
        name="">
        <color
          rgba="0.792156862745098 0.819607843137255 0.933333333333333 1" />
      </material>
    </visual>
    <collision>
      <origin
        xyz="0 0 0"
        rpy="0 0 0" />
      <geometry>
        <mesh
          filename="package://mpccube/meshes/wheelfrontleft.STL" />
      </geometry>
    </collision>
  </link>
  <joint
    name="wfl"
    type="continuous">
    <origin
      xyz="-0.189 0.31 -0.142"
      rpy="0 0 0" />
    <parent
      link="base_link" />
    <child
      link="wheelfrontleft" />
    <axis
      xyz="-1 0 0" />
  </joint>
  <link
    name="wheelbackrighttop">
    <inertial>
      <origin
        xyz="0 0 0"
        rpy="0 0 0" />
      <mass
        value="0.05" />
      <inertia
        ixx="7.16E-06"
        ixy="0"
        ixz="0"
        iyy="3.6E-06"
        iyz="0"
        izz="3.6E-06" />
    </inertial>
    <visual>
      <origin
        xyz="0 0 0"
        rpy="0 0 0" />
      <geometry>
        <mesh
          filename="package://mpccube/meshes/wheelbackrighttop.STL" />
      </geometry>
      <material
        name="">
        <color
          rgba="0.792156862745098 0.819607843137255 0.933333333333333 1" />
      </material>
    </visual>
    <collision>
      <origin
        xyz="0 0 0"
        rpy="0 0 0" />
      <geometry>
        <mesh
          filename="package://mpccube/meshes/wheelbackrighttop.STL" />
      </geometry>
    </collision>
  </link>
  <joint
    name="wbrt"
    type="continuous">
    <origin
      xyz="0.189 -0.325 0.30"
      rpy="0 0 0" />
    <parent
      link="base_link" />
    <child
      link="wheelbackrighttop" />
    <axis
      xyz="1 0 0" />
  </joint>
  <link
    name="wheelbacklefttop">
    <inertial>
      <origin
        xyz="0 0 0"
        rpy="0 0 0" />
      <mass
        value="0.05" />
      <inertia
        ixx="7.16E-06"
        ixy="0"
        ixz="0"
        iyy="3.6E-06"
        iyz="0"
        izz="3.6E-06" />
    </inertial>
    <visual>
      <origin
        xyz="0 0 0"
        rpy="0 0 0" />
      <geometry>
        <mesh
          filename="package://mpccube/meshes/wheelbacklefttop.STL" />
      </geometry>
      <material
        name="">
        <color
          rgba="0.792156862745098 0.819607843137255 0.933333333333333 1" />
      </material>
    </visual>
    <collision>
      <origin
        xyz="0 0 0"
        rpy="0 0 0" />
      <geometry>
        <mesh
          filename="package://mpccube/meshes/wheelbacklefttop.STL" />
      </geometry>
    </collision>
  </link>
  <joint
    name="wblt"
    type="continuous">
    <origin
      xyz="-0.189 -0.325 0.30"
      rpy="0 0 0" />
    <parent
      link="base_link" />
    <child
      link="wheelbacklefttop" />
    <axis
      xyz="1 0 0" />
  </joint>
  <link
    name="wheelfrontrighttop">
    <inertial>
      <origin
        xyz="0 0 0"
        rpy="0 0 0" />
      <mass
        value="0.05" />
      <inertia
        ixx="7.16E-06"
        ixy="0"
        ixz="0"
        iyy="3.6E-06"
        iyz="0"
        izz="3.6E-06" />
    </inertial>
    <visual>
      <origin
        xyz="0 0 0"
        rpy="0 0 0" />
      <geometry>
        <mesh
          filename="package://mpccube/meshes/wheelfrontrighttop.STL" />
      </geometry>
      <material
        name="">
        <color
          rgba="0.792156862745098 0.819607843137255 0.933333333333333 1" />
      </material>
    </visual>
    <collision>
      <origin
        xyz="0 0 0"
        rpy="0 0 0" />
      <geometry>
        <mesh
          filename="package://mpccube/meshes/wheelfrontrighttop.STL" />
      </geometry>
    </collision>
  </link>
  <joint
    name="wfrt"
    type="continuous">
    <origin
      xyz="0.189 0.325 0.30"
      rpy="0 0 0" />
    <parent
      link="base_link" />
    <child
      link="wheelfrontrighttop" />
    <axis
      xyz="-1 0 0" />
  </joint>
  <link
    name="wheelfrontlefttop">
    <inertial>
      <origin
        xyz="0 0 0"
        rpy="0 0 0" />
      <mass
        value="0.05" />
      <inertia
        ixx="7.16E-06"
        ixy="0"
        ixz="0"
        iyy="3.6E-06"
        iyz="0"
        izz="3.6E-06" />
    </inertial>
    <visual>
      <origin
        xyz="0 0 0"
        rpy="0 0 0" />
      <geometry>
        <mesh
          filename="package://mpccube/meshes/wheelfrontlefttop.STL" />
      </geometry>
      <material
        name="">
        <color
          rgba="0.792156862745098 0.819607843137255 0.933333333333333 1" />
      </material>
    </visual>
    <collision>
      <origin
        xyz="0 0 0"
        rpy="0 0 0" />
      <geometry>
        <mesh
          filename="package://mpccube/meshes/wheelfrontlefttop.STL" />
      </geometry>
    </collision>
  </link>
  <joint
    name="wflt"
    type="continuous">
    <origin
      xyz="-0.189 0.325 0.30"
      rpy="0 0 0" />
    <parent
      link="base_link" />
    <child
      link="wheelfrontlefttop" />
    <axis
      xyz="1 0 0" />
  </joint>
  <gazebo>
    <plugin name="mpccube_plugin" filename="libmpccubeplugin.so">
      <updateRate>40</updateRate>
      <publishTf>true</publishTf>
      <rotorThrustCoeff>0.00025</rotorThrustCoeff>
      <rotorTorqueCoeff>0.000075</rotorTorqueCoeff>
    </plugin>
  </gazebo>

  <link name="rangetop_link">
    <inertial>
      <origin xyz="0 0 0" rpy="0 0 0" />
      <mass value="0.0001" />
      <inertia ixx="0.0001" ixy="0" ixz="0" iyy="0.0001" iyz="0" izz="0.0001" />
    </inertial>
    <visual>
      <origin xyz="0 0 0" rpy="0 0 0" />
      <geometry>
        <box size="0.015 0.015 0.015" />
      </geometry>
      <material name="">
        <color rgba="0.792156862745098 0.819607843137255 0.933333333333333 1" />
      </material>
    </visual>
    <collision>
      <origin xyz="0 0 0" rpy="0 0 0" />
      <geometry>
        <box size="0.015 0.015 0.015" />
      </geometry>
    </collision>
  </link>
  <joint name="rangetop_joint" type="fixed">
    <parent link="base_link"/>
    <child link="rangetop_link"/>
    <origin xyz="0 0.162 0.23" rpy="0 0 0"/>
  </joint>
  <gazebo reference="rangetop_link">
    <sensor type="ray" name="head_lidar_sensor">
      <pose>0 0 0 0 0 0</pose>
      <visualize>false</visualize>
      <update_rate>20</update_rate>
      <ray>
        <scan>
          <horizontal>
            <samples>20</samples>
            <resolution>1</resolution>
            <min_angle>0.785</min_angle>
            <max_angle>2.356</max_angle>
          </horizontal>
        </scan>
        <range>
          <min>0.1</min>
          <max>15</max>
          <resolution>0.025</resolution>
        </range>
        <noise>
          <type>gaussian</type>
          <mean>0.0</mean>
          <stddev>0.01</stddev>
        </noise>
      </ray>
      <plugin name="gazebo_ros_head_lidar_controller" filename="libgazebo_ros_laser.so">
        <topicName>/top_scan</topicName>
        <frameName>rangetop_link</frameName>
      </plugin>
    </sensor>
  </gazebo>
  <!-- Add second range finder laser -->
  <link name="rangebottom_link">
    <inertial>
      <origin xyz="0 0 0" rpy="0 0 0" />
      <mass value="0.0001" />
      <inertia ixx="0.0001" ixy="0" ixz="0" iyy="0.0001" iyz="0" izz="0.0001" />
    </inertial>
    <visual>
      <origin xyz="0 0 0" rpy="0 0 0" />
      <geometry>
        <box size="0.015 0.015 0.015" />
      </geometry>
      <material name="">
        <color rgba="0.792156862745098 0.819607843137255 0.933333333333333 1" />
      </material>
    </visual>
    <collision>
      <origin xyz="0 0 0" rpy="0 0 0" />
      <geometry>
        <box size="0.015 0.015 0.015" />
      </geometry>
    </collision>
  </link>
  <joint name="rangebottom_joint" type="fixed">
    <parent link="base_link"/>
    <child link="rangebottom_link"/>
    <origin xyz="0 0.162 -0.025" rpy="-1.571 0 0"/>
  </joint>
  <gazebo reference="rangebottom_link">
    <sensor type="ray" name="bottom_lidar_sensor">
      <pose>0 0 0 0 0 0</pose>
      <visualize>false</visualize>
      <update_rate>20</update_rate>
      <ray>
        <scan>
          <horizontal>
            <samples>20</samples>
            <resolution>1</resolution>
            <min_angle>0.785</min_angle>
            <max_angle>2.356</max_angle>
          </horizontal>
        </scan>
        <range>
          <min>0.06</min>
          <max>5</max>
          <resolution>0.025</resolution>
        </range>
        <noise>
          <type>gaussian</type>
          <mean>0.0</mean>
          <stddev>0.01</stddev>
        </noise>
      </ray>
      <plugin name="gazebo_ros_bottom_lidar_controller" filename="libgazebo_ros_laser.so">
        <topicName>/bottom_scan</topicName>
        <frameName>rangebottom_link</frameName>
      </plugin>
    </sensor>

  </gazebo>

</robot>